Workbook

Sheet Recap
A1: SUMMARY EXPENSES / REVENUS
A3: Earth month market 04/19/26 | D3: 65 clothes/accessories sold | E3: 16 home goods
A4: best friends pop-up 03/15/26 | D4: 59 items sold
A5: best friends pop-up 01/25/26 | D5: 49 items sold
A6: picnic pop up 12/6/25 | D6: 46 clothes sold | E6: 27 home goods | H6: Sales | I6: ='Women - Sold'!E2 +'Kids - SOLD'!E2+'Home goods - Sold'!E2+C8+C9+C10+C12+C13+C14 -> 24760.28
A7: pop up 11/15/25 | D7: 57 clothes sold
A8: market 10/05/25 | B8: revenu | C8: 707 | D8: 30 clothes | E8: 8 home goods
A9: solano stroll 2025 | B9: revenu | C9: 850 | D9: 36 clothes | E9: 12 home goods
A10: market 8/24 | B10: revenu | C10: 1218 | D10: 38 clothes | E10: 8 home goods
A11: pop up 6/14 | B11: revenu | D11: 7 clothes | F11: 165 total (included by item)
A12: Pop Up 5/17 | B12: revenu | C12: 500 | D12: 16 clothes | E12: 1 bag
A13: Bon Marché April 2025 | B13: revenu | C13: 1090 | D13: 38 clothes | E13: 20 home goods
A14: Bon Marché February 2025 | B14: revenu | C14: 1060
A15: women clothes purchase | B15: expense | C15: =-(Women!D2+'Women - Sold'!D2) -> -10069.04
A16: women clothes sold | B16: revenu | C16: ='Women - Sold'!E2 -> 16193.83
A17: women clothes shipping | B17: expense | C17: =-'Women - Sold'!F2 -> -762.51
A18: home goods purchase | B18: expense | C18: =-('Home goods'!D2+'Home goods - Sold'!D2) -> -1481.41
A19: home goods sold | B19: revenu | C19: ='Home goods - Sold'!E2 -> 2579.45
A20: kids purchases | B20: expense | C20: =-(Kids!D2+'Kids - SOLD'!D2) -> -176.9
A21: Kids sold | B21: revenu | C21: ='Kids - SOLD'!G2 -> 460.6
C23: =SUM(C8:C21) -> 12169.02

Sheet Women
A1: Brand | B1: what? | C1: size | D1: cost | E1: Sold | F1: Shipping | G1: Benefice net | H1: Market price | I1: Link
D2: =SUM(D3:D990) -> 4985.43
A3: 360 cashmere | B3: beige cashmere sweater | C3: S | D3: 10
A4: 7 for all mankind | B4: black cropped jeans | C4: 27 | D4: 4
A5: 7 for all mankind | B5: blue jeans | C5: 29
A6: A new day | B6: teal babydoll dress | C6: M | D6: 9
A7: abercrombie | B7: black tank top | C7: M | D7: 2.5
A8: Active USa | B8: black LS top | C8: S | D8: 6
A9: Adolfo Dominguez | B9: blue linen top | C9: 38
A10: AERO | B10: khaki sweatpants | C10: XS
A11: AGL | B11: bordeaux shoes | C11: 38 | D11: 4.5
A12: Agnes B | B12: white LS top | D12: 6.5
A13: Akashi Kama | B13: green jacket | C13: S | D13: 10
A14: Alessandra Olivia | B14: green linen top | C14: S | D14: 5
A15: Alessandra Olivia | B15: blue linen top | C15: XS | D15: 5
A16: Alessia Pacini | B16: white linen blouse | C16: S | D16: 6
A17: Alessia Pacini | B17: cream linen jacket | C17: S | D17: 6.5
A18: Alex Mill | B18: blue pants | C18: 6 | D18: 3
A19: All Bird | B19: black wool sneakers | C19: 9 | D19: 2.5
A20: American Eagle | B20: cream dress, SS | C20: S | D20: 6 | H20: stain
A21: American Eagle | B21: blue/red dress | C21: 2
A22: american giant | B22: cotton hoodie | C22: XS | D22: 5
A23: amour vert | B23: white/beige LS top | C23: S | D23: 5
A24: amour vert | B24: black/green LS top | C24: XS | D24: 6
A25: amour vert | B25: navy silk dress | C25: S | D25: 9
A26: amour vert | B26: grey LS top | C26: S | D26: 6.5
A27: amour vert | B27: green wool cropped sweater | C27: S | D27: 3
A28: amour vert | B28: floral SS top | C28: L | D28: 3
A29: amour vert | B29: black white dots top | C29: XS | D29: 5
A30: amour vert | B30: grey stripes tee | C30: S | D30: 5
A31: amour vert | B31: BW chevron sweater | C31: XS | D31: 10
A32: amour vert | B32: grey top LS with front knot | C32: XS | D32: 7.3
A33: amour vert | B33: navy/white dress | C33: M | D33: 10
... A35: amour vert | B35: navy wool cardigan | C35: XS | D35: 20
A36: amour vert | B36: black jacket | C36: S
A37: amour vert | B37: black top LS vneck | C37: XS | D37: 8.1
A38: Amour vert | B38: beige wool skirt | C38: M | D38: 7.3
A39: Andantini | B39: leather cross body bag | D39: 15
A40: ann taylor | B40: black cashmerre turtleneck | C40: XS | D40: 12.5
A41: anne Klein | B41: navy silk blouse | C41: 8P | D41: 6
...

Sheet Women - Sold
A1: Brand | B1: what? | C1: size | D1: cost | E1: Sold | F1: Shipping | G1: Benefice net | H1: Event | I1: Link
D2: =SUM(D3:D1250) -> 5083.61 | E2: =SUM(E3:E1250) -> 16193.83 | F2: =SUM(F3:F1250) -> 762.51
A3: 1045 park | B3: vintage black top | C3: 5 | D3: 4 | E3: 25 | F3: 0 | G3: =E3-F3-D3 -> 21 | H3: picnic
A4: 120 Lino | B4: black/white dots shirt | C4: 44 | D4: 6 | E4: 30 | F4: 0 | G4: =E4-F4-D4 -> 24 | H4: 46131
A5: abercrombie | B5: dark blue/black sweater puff S | C5: S | D5: 0 | H5: 45767
A6: abercrombie | B6: blue peasant shirt | C6: M | D6: 7 | H6: solano stroll
A7: abercrombie | B7: blue open cardigan | C7: XS/S | H7: 45893
A8: A new day | B8: long brick dress | C8: S | D8: 7.49 | E8: 31.5 | F8: 6.35 | G8: =E8-F8-D8 -> 17.66
A9: Adidas | B9: black jacket | C9: S | H9: solano stroll | I9: sold 30
A10: Agnes B | B10: black tee | D10: 5 | E10: 20 | F10: 0 | G10: =E10-F10-D10 -> 15 | H10: 46131
A11: Agnes B | B11: Blue sweater | C11: 2 | D11: 8.1 | E11: 77.43 | F11: 4.49 | G11: =E11-F11-D11 -> 64.84 | H11: NB
A12: aiavu | B12: cashmere stripe sweater | C12: M | D12: 3.5 | E12: 67.84 | F12: 5.37 | G12: =E12-F12-D12 -> 58.97 | H12: NB
A13: Alex Mill | B13: Blue linen shirt | C13: M | D13: 9 | E13: 35 | F13: 0 | G13: =E13-D13 -> 26 | H13: 46096
A14: Alfani | B14: teal merino wool sweater | C14: S | D14: 7 | E14: 25 | F14: 0 | G14: =E14-D14 -> 18 | H14: 46047
A15: Allen Solly | B15: vintage wool vest | C15: S | D15: 10 | E15: 36.39 | F15: 6.39 | G15: =E15-F15-D15 -> 20
A16: Alynn | B16: silk scarf with books | D16: 1.5 | H16: 45696 | I16: gift
A17: American Eagle | B17: navy/grey sweater | C17: S | H17: 45893
A18: Amour vert | B18: navy blue wrap shirt | C18: M | D18: 13 | E18: 36 | F18: 0 | G18: =E18-F18-D18 -> 23 | H18: MT
A19: amour vert | B19: white tank top | C19: M | D19: 10 | H19: 45893
A20: amour vert | B20: red wool sweater | C20: S | D20: 4 | E20: 30 | F20: 0 | G20: =E20-F20-D20 -> 26 | H20: 45976
A21: amour vert | B21: cream SL knitted top | C21: XS | D21: 5 | E21: 30 | F21: 0 | G21: =E21-D21 -> 25 | H21: 46096
A22: Amour vert | B22: grey open cardigan | C22: M | D22: 7 | E22: 30 | F22: 0 | G22: =E22-F22-D22 -> 23 | H22: picnic
A23: amour vert | B23: green floral top | C23: XS | D23: 17 | H23: solano stroll
A24: amour vert | B24: silk jumpsuit | C24: M | D24: 5 | E24: 50 | F24: 3.47 | G24: =E24-F24-D24 -> 41.53
A25: amour vert | B25: silk floral blouse | C25: SP | D25: 7 | E25: 25 | F25: 0 | G25: =E25-F25-D25 -> 18 | H25: 45822
A26: Amour vert | B26: silk shirt | C26: M | D26: 10 | E26: 25 | F26: 3.5 | G26: =E26-F26-D26 -> 11.5 | I26: dry cleaner
A27: amour vert | B27: pink silk dress | C27: S | H27: 45696 | I27: sold $50
A28: Andrea Mabiani | B28: Blue leather bag | D28: 9 | H28: 45696 | I28: sold $40
A29: ann taylor | B29: black cashmere cardigan | C29: S | D29: 8.5 | E29: 40 | F29: 0 | G29: =E29-F29-D29 -> 31.5
A30: Ann Taylor | B30: black/brown/cream sweater | C30: S | D30: 8 | E30: 20 | F30: 0 | G30: =E30-F30-D30 -> 12
A31: ann taylor | B31: blue cashmere sweater | C31: M | D31: 15 | E31: 30 | F31: 0 | G31: =E31-F31-D31 -> 15
A32: Anne Fernwood | B32: vintage brown shirt | D32: 6.5 | E32: 25 | F32: 0 | G32: =E32-D32 -> 18.5 | H32: 46096
A33: anthropologie | B33: edme grey floral top | C33: 2 | D33: 6.3 | E33: 15 | F33: 0 | G33: =E33-F33-D33 -> 8.7
A34: anthropologie | B34: pink cardigan with front design | C34: S | D34: 3.7 | E34: 25 | F34: 0 | G34: =E34-D34 -> 21.3 | H34: 46131
A35: anthropologie | B35: embroidered multicolor blouse | C35: S | D35: 6 | E35: 25 | F35: 0 | G35: =E35-D35 -> 19 | H35: 46131
A36: anthropologie | B36: SL red/pink blouse | C36: XL | D36: 6.3 | H36: 45767
A37: anthropologie | B37: long dress terracotta | C37: L | D37: 10 | H37: 45767
A38: anthropologie | B38: tropical dress | C38: XS | D38: 11 | H38: 45767
A39: anthropologie | B39: kakhi pants | C39: SP | D39: 10 | H39: 45794
A40: Aqua cashmere | B40: cream cashmere sweater | C40: S | D40: 9 | E40: 40 | F40: 0 | G40: =E40-D40 -> 31 | H40: 46096
...

Sheet Kids
A1: Brand | B1: what? | C1: size | D1: cost | E1: Sold | F1: Shipping | G1: Benefice net | H1: Market price | I1: Link
D2: =SUM(D5:D610) -> 86.65 | E2: =SUM(E11:E610) -> 0 | F2: =SUM(F11:F610) -> 0 | J2: 641
A3: angou | B3: floral jumpsuit | C3: 18mo | D3: 2
A4: art class | B4: black eyelet tank | C4: 12 | D4: 0
A5: art class | B5: green floral top | C5: 8 | D5: 0
A6: art class | B6: green tank top | C6: 6 | D6: 0
A7: baby organic | B7: jumsuit NWT | C7: 9mo | D7: 3
A8: banana republic | B8: yellow wool sweater | C8: M | D8: 9
A9: Bonpoint | B9: dark blue corduroy | C9: 4 | D9: 0
A10: bonpoint | B10: dark brown skirt | C10: 3 | D10: 0
A11: Boy + Girl | B11: stripe linen dress | C11: 6 | D11: 2 | I11: buttons changed
A12: Caramel | B12: dress with bloomer | C12: 1 | D12: 4
A13: Carter's | B13: brown jumpsuit | C13: 18mo | D13: 2
A14: Carter's | B14: white/gold onesie | C14: 2 | D14: 2.5
A15: cat and jack | B15: yellow cabana striped dress | C15: 11 | D15: 0
A16: cat and jack | B16: green jumpsuit | C16: 1 | D16: 1.5
A17: cat and jack | B17: turquoise dress | C17: 12 | D17: 0
A18: cat and jack | B18: light green dress | C18: 4 | D18: 3
A19: cat and jack | B19: BW skirt with bretelles | C19: 3 | D19: 4
A20: C&C California | B20: pink jacket | C20: 2 | D20: 2
A21: CFK | B21: navy shorts | C21: 5 | D21: 0
A22: CFK | B22: red stripes sweater | C22: 5 | D22: 0
A23: Cherokee | B23: denim vest | C23: 8 | D23: 0
A24: Cherokee | B24: blue/red/white stripes dress | C24: 8 | D24: 4
A25: club med | B25: swimming tee | D25: 0
A26: cotton on | B26: organic cotton white/grey pyjama | C26: 9mo | D26: 4
A27: crewcuts | B27: hot pink embroidery tunic | C27: 12 | D27: 0
A28: crewcuts | B28: navy/white stripes dress | C28: 10 | D28: 0
A29: cyrillus | B29: polka dots top | C29: 10 | D29: 0
A30: cyrillus | B30: peach dress | C30: 18m | D30: 0
A31: Destira | B31: gymnastics attire | D31: 0
A32: du pareil au meme | B32: dove sweater | C32: 5 | D32: 0
A33: Gap | B33: denim shorts with flowers | C33: 10 | D33: 5
A34: Gap kids | B34: tee bouées | C34: 8 | D34: 1
A35: grain de blé | B35: grey top | C35: 18m | D35: 0
A36: grayson mini | B36: stripes shorts | C36: 5 | D36: 1.15
A37: guess | B37: chambray jumpsuit | C37: 12 | D37: 0
A38: H&M | B38: black tank top | C38: 10 | D38: 0
A39: H&M | B39: tartan dress | C39: 1 | D39: 2.5
A40: H&M | B40: blue romper | C40: 18 | D40: 4
...

Sheet Kids - SOLD
A1: Brand | B1: what? | C1: size | D1: cost | E1: Sold | F1: Shipping | G1: Benefice net | H1: Market price | I1: Link
D2: =SUM(D5:D595) -> 90.25 | E2: =SUM(E5:E595) -> 562 | F2: =SUM(F5:F595) -> 11.15 | G2: =E2-F2-D2 -> 460.6 | I2: 1016.44 | J2: 641
A3: abercrombie kids | B3: navy ruffle dress | C3: 12 | D3: 2 | E3: 7.5 | F3: 0 | G3: =E3-D3-F3 -> 5.5 | H3: STC | I3: 46116
A4: baby gap | B4: pink coat | C4: 2 | D4: 4 | E4: 10.5 | F4: 0 | G4: =E4-D4-F4 -> 6.5 | H4: STC | J4: =E3+E8+E9+E10+E46+E52+E53 -> 40.5
A5: Carter's | B5: pyjama | C5: 6 | D5: 6 | E5: 4.5 | F5: 0 | G5: =E5-D5 -> -1.5 | H5: STC
A6: Carter's | B6: beige boy sweater with zipper | C6: 4 | D6: 2.5 | E6: 15 | F6: 0 | G6: =E6-F6-D6 -> 12.5
A7: cat and jack | B7: denim jacket | C7: 12 | D7: 0 | E7: 10 | F7: 0 | G7: =E7-F7-D7 -> 10
A8: cat and jack | B8: red/blue/white plaid dress | C8: 46211 | D8: 1.85 | E8: 4.5 | F8: 0 | G8: =E8-F8-D8 -> 2.65 | H8: STC | I8: 46142
A9: cat and jack | B9: Olive pinafore dress | C9: 4 | D9: 2 | E9: 4.5 | F9: 0 | G9: =E9-F9-D9 -> 2.5 | H9: STC | I9: 46122
A10: cat and jack | B10: rust long dress | C10: 12 | D10: 6.3 | E10: 4.5 | F10: 0 | G10: =E10-F10-D10 -> -1.8 | H10: STC | I10: 46116
A11: columbia | B11: 2 ski pants | D11: 0 | E11: 45 | F11: 0 | G11: =E11-F11-D11 -> 45
A12: crewcuts | B12: navy Brooklyn sweater | C12: 12 | D12: 8 | E12: 7.5 | F12: 0 | G12: =E12-F12-D12 -> -0.5 | H12: STC
A13: cynthia rowley | B13: unicorn sweater | C13: 4 | D13: 3.5 | E13: 10.5 | F13: 0 | G13: =E13-F13-D13 -> 7 | H13: STC
A14: everlane | B14: blue jacket | C14: 3 | D14: 6 | E14: 4.5 | F14: 0 | G14: =E14-F14-D14 -> -1.5 | H14: STC
A15: firsts impressions | B15: red sweater | C15: 9mo | D15: 5 | E15: 10 | F15: 0 | G15: =E15-F15-D15 -> 5
A16: gap | B16: floral jeans | C16: 12 | D16: 0 | E16: 7.5 | F16: 0 | G16: =E16-D16 -> 7.5 | H16: STC | I16: 46102
A17: Gap | B17: pink stripes LS tee | C17: 10 | D17: 0 | E17: 3 | F17: 0 | G17: =E17-D17 -> 3 | H17: STC
A18: gap | B18: pink shirt with embroidery | C18: 10 | D18: 0 | E18: 5 | F18: 0 | G18: =E18-F18-D18 -> 5
A19: H&M | B19: pink dress LS | C19: 7 | D19: 3 | E19: 10 | F19: 0 | G19: =E19-F19-D19 -> 7
A20: H&M | B20: pink floral blouse | C20: 12 | D20: 0 | E20: 5 | F20: 0.4 | G20: =E20-F20-D20 -> 4.6
A21: h&M | B21: blue stripes top | C21: 7 | D21: 0 | E21: 4.5 | F21: 0 | G21: =E21-F21-D21 -> 4.5 | H21: STC | I21: 46082
A22: H&M | B22: libellules cardigan | C22: 8 | D22: 0 | E22: 7.5 | F22: 0 | G22: =E22-F22-D22 -> 7.5 | H22: STC
A23: handmade | B23: pink cotton cardigan | C23: 3 | D23: 2.5 | E23: 20 | F23: 0 | G23: =E23-F23-D23 -> 17.5
A24: Hannah Anderson | B24: girls dress checkers | C24: 4 | D24: 3 | E24: 15 | F24: 0 | G24: =E24-F24-D24 -> 12
A25: Hannah Anderson | B25: fair Isle sweater | C25: 12 | D25: 0 | E25: 9 | F25: 0 | G25: =E25-F25-D25 -> 9 | H25: STC
A26: HM | B26: cat dress | C26: 3 | D26: 0 | E26: 5 | F26: 0 | G26: =E26-F26-D26 -> 5 | H26: picnic
A27: jacadi | B27: snow suit | C27: 18mo | D27: 0 | E27: 60 | F27: 0 | G27: =E27-F27-D27 -> 60
A28: La queue du chat | B28: blue overall | C28: 3 | D28: 0 | E28: 15 | F28: 1.25 | G28: =E28-F28-D28 -> 13.75
A29: La queue du chat | B29: pink dress | C29: 4 | D29: 0 | E29: 15 | F29: 1.25 | G29: =E29-F29-D29 -> 13.75
A30: M&S | B30: pink LS blouse | C30: 2 | D30: 2 | E30: 10 | F30: 0 | G30: =E30-F30-D30 -> 8
A31: Monoprix | B31: bensimon bloomer | C31: 3 | D31: 0 | E31: 6 | F31: 0 | G31: =E31-D31-F31 -> 6 | I31: 46106
A32: Monoprix | B32: red floral dress | C32: 4 | D32: 0 | E32: 7.5 | F32: 0 | G32: =E32-D32-F32 -> 7.5 | H32: STC | I32: 46100
A33: Monoprix | B33: red stripes overall | C33: 3 | D33: 0 | E33: 10 | F33: 1.25 | G33: =E33-F33-D33 -> 8.75
A34: Old Navy | B34: flower dress LS | C34: 8 | D34: 5 | E34: 10 | F34: 0 | G34: =E34-F34-D34 -> 5
A35: old navy | B35: red skirt | C35: 2 | D35: 2 | E35: 5 | F35: 1.25 | G35: =E35-F35-D35 -> 1.75
A36: old navy | B36: pink denim skirt | C36: 12 | D36: 0 | E36: 4.5 | F36: 0 | G36: =E36-D36 -> 4.5 | H36: STC | I36: 46109
A37: old navy | B37: beige floral top | C37: 8 | D37: 0 | E37: 4.5 | F37: 0 | G37: =E37-D37 -> 4.5 | H37: STC
A38: Old Navy | B38: jean shorts | C38: 10yo | D38: 0 | E38: 4.5 | F38: 0 | G38: =E38-D38 -> 4.5 | H38: STC
A39: Osh Kosh | B39: sparkle sweater | C39: 3 | D39: 0 | E39: 4.5 | F39: 0 | G39: =E39-D39 -> 4.5 | H39: STC
A40: OshKosh | B40: blue thick cardigan | C40: 4 | D40: 2.5 | E40: 15 | F40: 0 | G40: =E40-F40-D40 -> 12.5
...

Sheet Home goods
A1: Brand | B1: what? | C1: size | D1: cost | E1: Sold | F1: Shipping | G1: Benefice net | H1: Market price | I1: Link
D2: =SUM(D4:D376) -> 803.11
A3: Aladdin | B3: Minuet bowl | D3: 5
A4: anri | B4: music box | D4: 2
A5: avon | B5: milk glass creamer | D5: 3
A6: aynsley | B6: wild tudor trinket | D6: 2
A7: baker and cold | B7: Old english handpainted / 1930 | C7: 7" plate | D7: 1.5 | H7: 20 | I7: https://www.ebay.com/itm/285534465724
A8: baker and cold | B8: Old english handpainted / 1930 / 2 bowls | D8: 3 | H8: 20
A9: baum bros | B9: small cream bowl | D9: 6
A10: Beatrix Potter | B10: peter rabbit mug | D10: 1.5
A11: Beatrix Potter | B11: peter rabbit mug | D11: 1.5
A12: Boleslawiec | B12: gravy sauce pan | D12: 15
A13: Boleslawiec | B13: lidded handled bowl | D13: 25
A14: Boop | B14: floral plate | D14: 3
A15: Boston | B15: handmade pot | D15: 1
A16: Castleton China | B16: gloria plate | D16: 1.5
A17: CBB | B17: handmade bowl | D17: 3.5
A18: Ceramiche Tadinate | B18: old italian dish | D18: 3.5 | H18: 30 | J18: https://www.ceramichetadinate.it/
A19: Churchill england | B19: 3 bowls, Fresco collection | C19: 8" | D19: 4.5 | I19: https://www.replacements.com/china-churchill-fresco-blue-coupe-soup-bowl/p/59337491
A20: CLG CO | B20: milk glass vase | D20: 3
A21: Colonial Candle | B21: vintage japanese candle holder | D21: 7
A22: Corelle by Corning | B22: 7 cups / Butterfly gold collection | C22: 3.5" | D22: 10.5 | H22: 10 | I22: https://www.replacements.com/china-corning-butterfly-gold-corelle/c/16777
A23: Corelle by Corning | B23: 8 saucers / butterfly gold collection | C23: 6" | D23: 5.6 | H23: 10 | I23: https://www.replacements.com/china-corning-butterfly-gold-corelle/c/16777
A24: corelle by Corning | B24: 2 saucers - blue pattern | D24: 1.4
A25: corning ware | B25: blue cornflower A1B | D25: 6.49
A26: corning ware | B26: blue cornflower P43B | D26: 5.98
A27: corning ware | B27: blue cornflower P4B | D27: 4.5
A28: corning ware | B28: Echalote P322 | D28: 7 | H28: keep | I28: https://www.ebay.com/itm/164033092126
A29: corning ware | B29: 3 qt casserole dish L'Echalote A3B | D29: 8 | H29: keep | J29: https://www.replacements.com/china-corning-spice-of-life-centura-3-quart-square-casserole-no-lid/p/20528411
A30: corning ware | B30: Echalote - A1B, 1 quart dish | D30: 4.7 | H30: keep
A31: corning ware | B31: 1.5qt casserole dish | D31: 4.5 | H31: keep | J31: https://www.replacements.com/china-corning-spice-of-life-centura-1-5-quart-square-casserole-no-lid/p/60528431
A32: corning ware | B32: Echalote P43B dish | D32: 3 | H32: keep
A33: corning ware | B33: wildflower dish A2B | D33: 8 | H33: 25 | I33: https://www.replacements.com/china-corning-wildflower-corelle-2-quart-square-casserole-no-lid/p/22831971
A34: corning ware | B34: F5B round dish with lid | D34: 6.5 | I34: https://www.replacements.com/china-corning-french-white-1-5-qt-round-covered-casserole/p/33858561
A35: corning ware | B35: round pie dish french white - F3B | D35: 4.5
A36: Country Harvest | B36: Apple pie dish | D36: 6
A37: Crate and Barrel | B37: golden candle holder, short | D37: 2
A38: Crate and Barrel | B38: tokyo small tray | D38: 1
A39: Crate and Barrel | B39: 4 green bowls | D39: 4
A40: Crate and Barrel | B40: 4 Winter Gems Appetizer plates | D40: 5
...

Sheet Home goods - Sold
A1: Brand | B1: what? | C1: size | D1: cost | E1: Sold | F1: Shipping | G1: Benefice net | H1: Market price | I1: Link
D2: =SUM(D3:D477) -> 678.3 | E2: =SUM(E3:E477) -> 2579.45 | F2: =SUM(F3:F477) -> 26.44
A3: Andrea by Sadek | B3: 2 saucers with flowers | D3: 3.5 | H3: 45767
A4: Anthropologie | B4: set of 4 green coasters | D4: 6 | E4: 15 | F4: 0 | G4: =E4-F4-D4 -> 9 | H4: 46131
A5: Anthropologie | B5: lion mug | D5: 1 | E5: 10 | F5: 0 | G5: =E5-F5-D5 -> 9 | H5: picnic
A6: Anthropologie | B6: ceramic french press | D6: 4.5 | E6: 50 | F6: 0 | G6: =E6-F6-D6 -> 45.5
A7: Anthropologie | B7: 4 plates | D7: 5 | E7: 15 | F7: 0 | G7: =E7-F7-D7 -> 10
A8: Anthropologie | B8: cat mug | D8: 1 | E8: 10 | F8: 0 | G8: =E8-F8-D8 -> 9
A9: At Home | B9: pink/yellow mug | D9: 1.5 | E9: 5 | F9: 0 | G9: =E9-F9-D9 -> 3.5
A10: Aza selection | B10: brown soliflore | E10: 10 | F10: 0 | G10: =E10-F10-D10 -> 10
A11: Beatrix Potter | B11: piggybank | D11: 3.5 | H11: 45893
A12: Beatrix Potter | B12: Benjamin bunny mug | D12: 1.5 | E12: 10 | F12: 0 | G12: =E12-F12-D12 -> 8.5 | H12: 46131
A13: Beatrix Potter | B13: Benjamin bunny mug | D13: 1.5 | E13: 10 | F13: 0 | G13: =E13-F13-D13 -> 8.5 | H13: 46131
A14: Beatrix Potter | B14: Small peter rabbit cup | D14: 1.5 | E14: 10 | F14: 0 | G14: =E14-F14-D14 -> 8.5 | H14: 46131
A15: Beatrix Potter | B15: Small peter rabbit cup | D15: 1.5 | E15: 10 | F15: 0 | G15: =E15-F15-D15 -> 8.5 | H15: 46131
A16: better homes & gardens | B16: Jute tablerunner | D16: 3 | E16: 20 | F16: 0 | G16: =E16-F16-D16 -> 17 | H16: 46131
A17: Bia cordon bleu | B17: 4 large cheese plates | D17: 9.5 | H17: 45696 | I17: sold 25 | J17: https://www.etsy.com/listing/1484516007/camembert-depot-paris-four-plate-serving?ga_order=most_relevant&ga_search_type=all&ga_view_type=gallery&ga_search_query=bia+cordon+bleu+camembert&ref=sr_gallery-1-13&content_source=4caf86f05116436909f51f2249291922ec7bc4bb%253A1484516007&search_preloaded_img=1&organic_search_click=1
A18: Bia cordon bleu | B18: 4 small cheese plates | D18: 7.5 | H18: Solano stroll
A19: Biltons | B19: cat mug, made in England | D19: 2.5 | H19: Solano stroll
A20: Bluelounge | B20: desk | D20: 0 | E20: 220 | F20: 0 | G20: =E20-F20-D20 -> 220
A21: Bodum | B21: columbia french press | D21: 5.8 | E21: 40 | F21: 0 | G21: =E21-F21-D21 -> 34.2
A22: bodum | B22: columbia coffee maker | D22: 3.5 | E22: 30 | F22: 0 | G22: =E22-F22-D22 -> 26.5 | H22: 30 | I22: https://www.bodum.com/us/en/1308-16-bodum-columbia
A23: Booths China | B23: 1 round plate | D23: 4 | E23: 12 | F23: 0 | G23: =E23-D23 -> 8 | H23: 46131
A24: Booths China | B24: 1 oval dish | D24: 4 | E24: 15 | F24: 0 | G24: =E24-D24 -> 11 | H24: 46131
A25: Castleton China | B25: gloria small bowl | D25: 1.5 | E25: 5 | F25: 0 | G25: =E25-F25-D25 -> 3.5 | H25: picnic
A26: cb2 | B26: pillowcase | D26: 0 | E26: 10 | F26: 0 | G26: =E26-F26-D26 -> 10
A27: Christophe Pichon | B27: brown salad bowl | D27: 4.5 | E27: 15 | F27: 0 | G27: =E27-F27-D27 -> 10.5 | H27: picnic
A28: colorstax | B28: blue gratin dish | D28: 3.5 | H28: Solano stroll
A29: corelle by Corning | B29: 4 cups / Butterfly gold collection | D29: 8.8 | E29: 25 | F29: 0 | G29: =E29-F29-D29 -> 16.2 | H29: picnic
A30: corning ware | B30: french white cocotte 4L F14B | D30: 12.8 | E30: 35 | F30: 0 | G30: =E30-D30 -> 22.2 | I30: https://www.etsy.com/listing/1182568373/corning-ware-french-white-f-14-b-4-liter?show_sold_out_detail=1&ref=nla_listing_details
A31: corning ware | B31: buffet server B4B, 4qt | D31: 17.2 | E31: 50 | F31: 0 | G31: =E31-F31-D31 -> 32.8 | I31: https://www.moose-r-us.com/shop/vintage-corning-ware-buffet-server-4-quart-white-casserole-stew-usa-cooking-pot/
A32: Crate and Barrel | B32: blue/green speckled ombre barrel vase | C32: 6.25”x 7” | D32: 4.5 | H32: 45935 | I32: https://www.ebay.com/itm/386942557783 | J32: made in Portugal, stamped, The blue color has an eggshell finish and the green is glossy.
A33: Crate and Barrel | B33: set of 4 east coast trays | D33: 5 | H33: 45893
A34: Crate and Barrel | B34: set of 4 mugs | D34: 6 | E34: 20 | F34: 0 | G34: =E34-F34-D34 -> 14
A35: Crate and Barrel | B35: white chip & dip | D35: 4 | E35: 5 | F35: 0 | G35: =E35-D35 -> 1 | H35: 15 | I35: https://www.ebay.com/itm/313911293815
A36: Crate and Barrel | B36: 2 martini glasses, crafted in mexico, Granada collection | C36: 5.5 x 6.5 | D36: 3 | E36: 20 | F36: 0 | G36: =E36-F36-D36 -> 17 | H36: picnic | I36: https://www.ebay.com/itm/195760494918 | J36: hand blown in Mexico, color swirl, no chips or cracks
A37: Crate and Barrel | B37: golden candle holder | D37: 3 | E37: 20 | F37: 0 | G37: =E37-F37-D37 -> 17 | H37: picnic
A38: Crate and Barrel | B38: ceramic sake bottle | C38: 6" tall | D38: 2.5 | H38: 45767 | I38: https://poshmark.com/listing/Crate-and-Barrel-silver-white-ceramic-sake-bottle-vase-677e7e0f64f5a286526f0d21
A39: cristal d'arques | B39: alexandrite neodymium crystal vase | D39: 3.5 | H39: 45767 | I39: https://www.etsy.com/listing/1689223138/vase-vintage-en-cystal-pae-crystal
A40: Crystal clear | B40: 2 candle holders made in Romania | D40: 10 | E40: 45 | F40: 0 | G40: =E40-F40-D40 -> 35 | H40: 40 | I40: https://www.etsy.com/listing/1520019982/crystal-clear-hand-crafted-crystal?ref=share_v4_lx
...
